Workbook
Name totalItemsInStock: Dashboard!$H$4

Sheet Check-out
A1: Check-out date | B1: Stock keeping unit (SKU) | C1: {=IF(ROW(A1:A998)=1,"Item name (automatic fill)",IF(B1:B998="","",VLOOKUP(B1:B998,'Check-in'!B:C,2,FALSE)))} -> Item name (automatic fill) | D1: Quantity | E1: {=IF(ROW(A1:A998)=1,"Unit of measure (automatic fill)",IF(B1:B998="","",VLOOKUP(B1:B998,'Check-in'!B:E,4,FALSE)))} -> Unit of measure (automatic fill)
A2: 44808
B3: ENPG | C3: Party Games | D3: 1 | E3: unit

Sheet Check-in
A1: Date | B1: Stock keeping unit (SKU) | C1: Item name | D1: Quantity | E1: Unit of measure
A2: 45008 | B2: BAAF | C2: Air Freshener | D2: 2 | E2: unit
A3: 45008 | B3: ELAC | C3: Alarm Clocks | D3: 7 | E3: unit
A4: 45008 | B4: BAAS | C4: Alcohol Swabs/Lens Wipes | D4: 20 | E4: unit
A5: 45008 | B5: KIAF | C5: Aluminum Foil | D5: 1 | E5: unit
A6: 45008 | B6: BAAN | C6: Antiseptic | D6: 2 | E6: unit
B7: BABP | C7: Baby Powder | E7: unit
A8: 45008 | B8: KIBP | C8: Baking Pans | D8: 2 | E8: unit
A9: 45008 | B9: BABA | C9: Band-Aids | D9: 6 | E9: unit
B10: KIBA | C10: Barware | E10: unit
B11: LABA | C11: Baskets | E11: unit
B12: ARBE | C12: Beads | E12: unit
A13: 45008 | B13: FUBR | C13: Bed Risers | D13: 9 | E13: unit
B14: OFBC | C14: Binder Clips | E14: unit
A15: 45008 | B15: OFBI | C15: Binders | D15: 76 | E15: unit
B16: STBI | C16: Bins | E16: unit
B17: APBL | C17: Blenders | E17: unit
A18: 45008 | B18: ENBG | C18: Board Games | D18: 13 | E18: unit
B19: BABW | C19: Body Wash | E19: unit
A20: 45008 | B20: ENBO | C20: Books | D20: 734 | E20: unit
A21: 45008 | B21: KIBO | C21: Bottles | D21: 28 | E21: unit
A22: 45008 | B22: KIJA | C22: Bottles/Jars/Misc | D22: 2 | E22: unit
A23: 45008 | B23: KIBW | C23: Bowls | D23: 11 | E23: unit
B24: CPBR | C24: Brushes | E24: unit
A25: 45008 | B25: BABS | C25: Bug Spray | D25: 1 | E25: unit
A26: 45008 | B26: OFCA | C26: Calculators | D26: 7 | E26: unit
A27: 45008 | B27: KICA | C27: Can Openers | D27: 2 | E27: unit
B28: ARCA | C28: Canvas | E28: unit
A29: 45008 | B29: ENCD | C29: CDs | D29: 73 | E29: unit
B30: FUCH | C30: Chairs | E30: unit
A31: 45008 | B31: ARCK | C31: Chalk | D31: 7 | E31: unit
B32: ELCC | C32: Chargers/Cords | E32: unit
A33: 45008 | B33: KICH | C33: Chopsticks | D33: 3 | E33: unit
A34: 45008 | B34: KICS | C34: Coasters | D34: 1 | E34: unit
B35: KICF | C35: Coffee | E35: unit
A36: 45008 | B36: APCM | C36: Coffee Machines | D36: 5 | E36: unit
A37: 45008 | B37: KICO | C37: Colanders | D37: 2 | E37: unit
A38: 45008 | B38: ARCP | C38: Colored Pencils | D38: 15 | E38: unit
A39: 45011 | B39: HICS | C39: Command Strips | D39: 8 | E39: unit
A40: 45011 | B40: BACO | C40: Conditioner | D40: 1 | E40: unit
...

Sheet Dashboard
H3: TOTAL ITEMS IN STOCK | P3: SOLD OUT ITEMS
H4: =SUM('Current inventory list'!F2:F28) -> 1246 | P4: =IFERROR(__xludf.DUMMYFUNCTION("IFERROR(QUERY('Current inventory list'!A2:G28,""SELECT B WHERE F=0 LIMIT 9"",0),""None"")"),"Baby Powder") -> Baby Powder
P5: =IFERROR(__xludf.DUMMYFUNCTION("""COMPUTED_VALUE"""),"Barware") -> Barware
P6: =IFERROR(__xludf.DUMMYFUNCTION("""COMPUTED_VALUE"""),"Baskets") -> Baskets
P7: =IFERROR(__xludf.DUMMYFUNCTION("""COMPUTED_VALUE"""),"Beads") -> Beads
B8: Inventory management | H8: TOP ITEMS | P8: =IFERROR(__xludf.DUMMYFUNCTION("""COMPUTED_VALUE"""),"Binder Clips") -> Binder Clips
E9: by | H9: IN | I9: =IFERROR(__xludf.DUMMYFUNCTION("QUERY('Current inventory list'!A2:G28,""SELECT B ORDER BY D DESC LIMIT 1"",0)"),"Books") -> Books | P9: =IFERROR(__xludf.DUMMYFUNCTION("""COMPUTED_VALUE"""),"Bins") -> Bins
P10: =IFERROR(__xludf.DUMMYFUNCTION("""COMPUTED_VALUE"""),"Blenders") -> Blenders
H11: OUT | I11: =IFERROR(__xludf.DUMMYFUNCTION("QUERY('Current inventory list'!A10:G28,""SELECT B ORDER BY E DESC LIMIT 1"",0)"),"Party Games") -> Party Games | P11: =IFERROR(__xludf.DUMMYFUNCTION("""COMPUTED_VALUE"""),"Body Wash") -> Body Wash
P12: =IFERROR(__xludf.DUMMYFUNCTION("""COMPUTED_VALUE"""),"Brushes") -> Brushes

Sheet Current inventory list
A1: {=UNIQUE(INDIRECT("'Check-in'!"&LEFT(ADDRESS(1,MATCH("Stock Keeping Unit (SKU)",'Check-in'!1:1,FALSE),4,TRUE))&":"&LEFT(ADDRESS(1,MATCH("Stock Keeping Unit (SKU)",'Check-in'!1:1,FALSE),4,TRUE))&""))} -> Stock keeping unit (SKU) | B1: {=IFERROR(VLOOKUP(A1:A1000,'Check-in'!B1:G1000,MATCH("ITEM NAME",'Check-in'!B1:G1,0),FALSE),"")} -> Item name | C1: {=IFERROR(VLOOKUP(A1:A1000,'Check-in'!B1:G1000,MATCH("UNIT OF MEASURE",'Check-in'!B1:G1,0),FALSE),"")} -> Unit of measure | D1: {=IF(ROW(A1:A1000)=1,"Check-in total",IF(A1:A1000="","",SUMIF(INDIRECT("'Check-in'!"&LEFT(ADDRESS(1,MATCH("Stock keeping unit (SKU)",'Check-in'!1:1,FALSE),4,TRUE))&":"&LEFT(ADDRESS(1,MATCH("Stock keeping unit (SKU)",'Check-in'!1:1,FALSE),4,TRUE))&""),A1:A1000,INDIRECT("'Check-in'!"&LEFT(ADDRESS(1,MATCH("Quantity",'Check-in'!1:1,FALSE),4,TRUE))&":"&LEFT(ADDRESS(1,MATCH("Quantity",'Check-in'!1:1,FALSE),4,TRUE))&""))))} -> Check-in total | E1: {=IF(ROW(A1:A1000)=1,"Check-out total",IF(A1:A1000="","",SUMIF(INDIRECT("'Check-out'!"&LEFT(ADDRESS(1,MATCH("Stock keeping unit (SKU)",'Check-out'!1:1,FALSE),4,TRUE))&":"&LEFT(ADDRESS(1,MATCH("Stock keeping unit (SKU)",'Check-out'!1:1,FALSE),4,TRUE))&""),A1:A1000,INDIRECT("'Check-out'!"&LEFT(ADDRESS(1,MATCH("Quantity",'Check-out'!1:1,FALSE),4,TRUE))&":"&LEFT(ADDRESS(1,MATCH("Quantity",'Check-out'!1:1,FALSE),4,TRUE))&""))))} -> Check-out total | F1: {=IF(ROW(A1:A1000)=1,"Inventory",IF(A1:A1000="","",(D1:D1000-E1:E1000)))} -> Inventory | G1: {=IF(ROW(A1:A1000)=1,"% Available",IFERROR(IF(F1:F1000="","",F1:F1000/D1:D1000),0))} -> % Available
A2: BAAF | B2: Air Freshener | C2: unit | D2: 2 | E2: 0 | F2: 2 | G2: 1
A3: ELAC | B3: Alarm Clocks | C3: unit | D3: 7 | E3: 0 | F3: 7 | G3: 1
A4: BAAS | B4: Alcohol Swabs/Lens Wipes | C4: unit | D4: 20 | E4: 0 | F4: 20 | G4: 1
A5: KIAF | B5: Aluminum Foil | C5: unit | D5: 1 | E5: 0 | F5: 1 | G5: 1
A6: BAAN | B6: Antiseptic | C6: unit | D6: 2 | E6: 0 | F6: 2 | G6: 1
A7: BABP | B7: Baby Powder | C7: unit | D7: 0 | E7: 0 | F7: 0 | G7: 0
A8: KIBP | B8: Baking Pans | C8: unit | D8: 2 | E8: 0 | F8: 2 | G8: 1
A9: BABA | B9: Band-Aids | C9: unit | D9: 6 | E9: 0 | F9: 6 | G9: 1
A10: KIBA | B10: Barware | C10: unit | D10: 0 | E10: 0 | F10: 0 | G10: 0
A11: LABA | B11: Baskets | C11: unit | D11: 0 | E11: 0 | F11: 0 | G11: 0
A12: ARBE | B12: Beads | C12: unit | D12: 0 | E12: 0 | F12: 0 | G12: 0
A13: FUBR | B13: Bed Risers | C13: unit | D13: 9 | E13: 0 | F13: 9 | G13: 1
... A240: KIZI | B240: Ziplocs | C240: unit | D240: 0 | E240: 0 | F240: 0 | G240: 0

Sheet Stickered Items
A1: Year of Entry | B1: Check-out Date | C1: Owner's Name | D1: Email | E1: Number | F1: Category | G1: Item | H1: Size | I1: Color | J1: Brand | Type | K1: Condition | M1: Notes
A2: 2023 | B2: 45163 | C2: Mustafa Elhassan | D2: melhassan@haverford.edu | E2: 2 | F2: Appliances | G2: Fridge - Freezer | H2: Cube | I2: Black | J2: Haier | L2: FALSE
A3: 2023 | B3: 45163 | C3: Yuko Zhuo | D3: yzhuo1@haverford.edu | E3: 4 | F3: Appliances | G3: Fridge - Freezer | H3: Mid | I3: White | J3: Midea | L3: FALSE | M3: Haverodeo Sticker
A4: 2022 | B4: 45163 | C4: Abigail Pruszinski | D4: apruszinsk@haverford.edu | E4: 5 | F4: Appliances | G4: Fridge - Freezer | H4: Large | I4: Black | J4: Midea | K4: Excellent | L4: TRUE | M4: Two Glass Shelves (wants to return early - post Thanksgiving Break) | Returned during the school year
A5: 2023 | B5: 45163 | C5: Hazel Alvarado | D5: halvarado@haverford.edu | E5: 6 | F5: Appliances | G5: Fridge - Freezer | H5: Seperate Freezer | I5: Silver | J5: Euhomy | K5: Great | L5: FALSE | M5: New to Program | Not Pictured!
A6: 2023 | B6: 45163 | C6: Grace Nasrallah | D6: gnasrallah@haverford.edu | E6: 10 | F6: Appliances | G6: Fridge - Freezer | H6: Seperate Freezer | J6: Insignia | L6: FALSE | M6: Could have possibly been returned, there is one matching description in the store
A7: 2023 | B7: 45163 | C7: Aida Standerford | D7: astanderfo@haverford.edu | E7: 12 | F7: Appliances | G7: Fridge - Freezer | H7: Seperate Freezer | I7: Silver | J7: Haier | L7: FALSE
A8: 2022 | B8: 45163 | C8: Citlali Camacho | D8: ccamacho@haverford.edu | E8: 14 | F8: Appliances | G8: Fridge - Freezer | H8: Large | I8: Silver | J8: Emerson | K8: Great | L8: FALSE | M8: Two Glass Shelves | Some Sticky Residue On top and Peeled Sticker On Front
A9: 2023 | B9: 45163 | C9: Ibinabo West | D9: iwest@haverford.edu | E9: 15 | F9: Appliances | G9: Fridge - Freezer | H9: Mid | I9: Black | J9: Insignia | L9: FALSE
A10: 2020 | B10: 45163 | C10: Damião Victor Andrade da Silva | D10: dandradeda@haverford.edu | E10: 16 | F10: Appliances | G10: Fridge - Freezer | H10: Mid | I10: Black | J10: Kenmore | K10: Great | L10: FALSE | M10: Two Shelves
A11: 2022 | B11: 45163 | C11: Samantha Fabel | D11: sfable@haverford.edu | E11: 17 | F11: Appliances | G11: Fridge - Freezer | H11: Mid | I11: Black | J11: RCA | L11: FALSE | M11: Stickers on the Front
A12: 2021 | B12: 45166 | C12: Jersson veliz Hernandez | D12: jvelizhern@haverford.edu | E12: 19 | F12: Appliances | G12: Fridge - Freezer | H12: Mid | I12: Black | J12: Haier | K12: Great | L12: FALSE | M12: One Glass Shelf | One Small Yellow Stain | Stickers on Front (Yeti, PoleOno, Tresor, Liverpool, Vmoda) | Some Door Staining
A13: 2023 | B13: 45163 | C13: Heshu Yin | D13: eyin@haverford.edu | E13: 20 | F13: Appliances | G13: Fridge - Freezer | H13: Mid | I13: Black | J13: Haier | L13: FALSE
A14: 2022 | B14: 45163 | C14: Mateo Kietzman | D14: mkietzman@haverford.edu | E14: 21 | F14: Appliances | G14: Fridge | H14: Mid | I14: Black | J14: Arctic Fresh | K14: Excellent | L14: FALSE | M14: Very Clean | Can Holder on Door | One Shelf
A15: 2023 | B15: 45163 | C15: Shakhzoda Mamadalieva | D15: smamadalie@haverford.edu | E15: 22 | F15: Appliances | G15: Fridge - Freezer | I15: Black | J15: Midea | L15: FALSE
A16: 2022 | B16: 45163 | C16: Dan Adamopulos | D16: dadamopulo@haverford.edu | E16: 23 | F16: Appliances | G16: Fridge - Freezer | H16: Mid | I16: Silver/Black | J16: Whirlpool | K16: Great | L16: FALSE | M16: One Shelf
A17: 2022 | B17: 45163 | C17: Wale Oguntomi | D17: woguntomi@haverford.edu | E17: 24 | F17: Appliances | G17: Fridge - Freezer | H17: Cube | I17: White | J17: Emerson | K17: Okay | L17: FALSE | M17: No Shelves | No Freezer Door | Missing Top of Hinge | No Bottom Door Bar | Residue on Front | Staining Inside
A18: 2022 | B18: 45163 | C18: Zoe Lin | D18: zlin1@haverford.edu | E18: 28 | F18: Appliances | G18: Fridge - Freezer | H18: Mid | I18: Silver/Black | J18: Whirlpool | K18: Great | L18: FALSE | M18: Some Slight Scratches | Two Shelves
A19: 2022 | B19: 45163 | C19: Ellie Park | D19: epark1@haverford.edu | E19: 33 | F19: Appliances | G19: Fridge - Freezer | H19: Large | I19: Silver | J19: Emerson | K19: Good | L19: FALSE | M19: Two Glass Shelves | Small Scratches on Top
A20: 2023 | B20: 45163 | C20: Angel Huitzil Huitzil | D20: ahuitzilhu@haverford.edu | E20: 34 | F20: Appliances | G20: Fridge - Freezer | H20: Cube | I20: Black | J20: Insignia | L20: FALSE
A21: 2020 | B21: 45163 | C21: Eugene Yang | D21: eyyang@haverford.edu | E21: 35 | F21: Appliances | G21: Fridge - Freezer | H21: Mid | I21: Silver | J21: SPT | K21: Great | L21: FALSE | M21: One Shelf
A22: 2022 | B22: 45163 | C22: Tyleena Cantillo | D22: tcantillo@haverford.edu | E22: 36 | F22: Appliances | G22: Fridge - Freezer | H22: Mid | I22: Black | J22: Kenmore | K22: Great | L22: FALSE | M22: One Shelf | Slight scratch on Front
A23: 2023 | B23: 45163 | C23: Ana Isabela Azumatan Aceituno | D23: iazumatana@haverford.edu | E23: 37 | F23: Appliances | G23: Fridge - Freezer | H23: Seperate Freezer | I23: Black | J23: Frigidaire | K23: Great | L23: FALSE | M23: Script Silver Text on Freezer Door
A24: 2023 | B24: 45163 | C24: Hannah Jensen-Sizelove | D24: hjensensiz@haverford.edu | E24: 39 | F24: Appliances | G24: Fridge - Freezer | I24: Black | J24: Danby Designer | L24: FALSE | M24: Stickered (Includes Kelly Sticker)
A25: 2023 | B25: 45163 | C25: Yasmin Choudhury | D25: ychoudhury@haverford.edu | E25: 41 | F25: Appliances | G25: Fridge - Freezer | H25: Seperate Freezer | I25: Black/Silver | J25: HiSense | L25: FALSE | M25: Blue Sticker on the Front, Pantone Sticker on the Side - Not Pictured
A26: 2023 | B26: 45163 | C26: Ethan Rezer | D26: erezer@haverford.edu | E26: 44 | F26: Appliances | G26: Fridge - Freezer | H26: Large | I26: Grey | J26: Whirlpool | K26: Good | L26: FALSE | M26: Missing Hinge Cover, No shelfs, Can Holder on Door (Sticker put on Left Side)
A27: 2022 | B27: 45163 | C27: Fatoumata Sow | D27: fsow@haverford.edu | E27: 46 | F27: Appliances | G27: Fridge - Freezer | H27: Cube | I27: Silver | J27: Sanyo | K27: Great | L27: FALSE | M27: Dent on Front | One Shelf
A28: 2020 | B28: 45166 | C28: Deep Patel | D28: dcpatel@haverford.edu | E28: 47 | F28: Appliances | G28: Fridge - Freezer | H28: Cube | I28: Black | J28: Insignia | K28: Good | L28: FALSE | M28: No Shelf | Some Scratches on Top
A29: 2023 | B29: 45163 | C29: Chrislove Lamour | D29: clamour@haverford.edu | E29: 50 | F29: Appliances | G29: Fridge - Freezer | H29: Seperate Freezer | I29: Black | J29: Insignia | L29: FALSE | M29: Not Pictured
A30: 2022 | B30: 45163 | C30: Uyen Tran | D30: utran@haverford.edu | E30: 52 | F30: Appliances | G30: Fridge - Freezer | H30: Large | I30: Black | J30: Magic Chef | K30: Excellent | L30: FALSE | M30: Three Glass Shelves | Large Freezer Component | Clear Door Accessories
A31: 2022 | B31: 45163 | C31: Anita Lau | D31: alau@haverford.edu | E31: 53 | F31: Appliances | G31: Fridge - Freezer | H31: Seperate Freezer | I31: Silver | J31: Whirlpool | K31: Excellent | L31: FALSE | M31: Two Shelves
A32: 2022 | B32: 45163 | C32: Theodore Rodriguez | D32: trodriguez@haverford.edu | E32: 54 | F32: Appliances | G32: Fridge - Freezer | H32: Seperate Freezer | I32: Silver | J32: Whirlpool | K32: Excellent | L32: FALSE | M32: Small dent on freezer door | One Shelf
A33: 2023 | B33: 45163 | C33: Melanee Coopwood | D33: mcoopwood@haverford.edu | E33: 55 | F33: Appliances | G33: Fridge - Freezer | H33: Seperate Freezer | I33: Silver | J33: Whirlpool | K33: Great | L33: FALSE | M33: Missing Photos
A34: 2021 | B34: 45163 | C34: Grace Hannigan | D34: ghannigan@haverford.edu | E34: 56 | F34: Appliances | G34: Fridge - Freezer | H34: Mid | I34: Silver | J34: Emerson | K34: Great | L34: FALSE | M34: Two Shelves | Can holder on Door | Star Stickers/Tape on Front | Some Slight Scratches on Top
A35: 2023 | B35: 45163 | C35: Emma Ganaj | D35: eganaj@haverford.edu | E35: 57 | F35: Appliances | G35: Fridge - Freezer | H35: Seperate Freezer | I35: Black | J35: Costway | L35: FALSE
A36: 2022 | B36: 45166 | C36: Qianzhi Zhao | D36: qzhao@haverford.edu | F36: Appliances | G36: Fridge | H36: Cube | I36: White | J36: Arctic Fresh | K36: Excellent | L36: FALSE | M36: Small car sticker on front | One Shelf
A37: 2020 | B37: 45176 | C37: Alicia Alvarado | D37: asalvarado@haverford.edu | F37: Appliances | G37: Fridge | H37: Cube | I37: Black | J37: Avalon | K37: Good | L37: FALSE | M37: No freezer door | One Shelf (Missing Shelf 2022) | Scuff on Upper Left Corner
A38: 2020 | B38: 45168 | C38: Carter Kroenke | D38: ckroenke@haverford.edu | F38: Appliances | G38: Fridge - Freezer | H38: Cube | I38: White | J38: Avanti | K38: Great | L38: FALSE | M38: No Shelf | Homemade (RE)use Store Label
A39: 2020 | B39: 45176 | C39: Fatoumata Bamba | D39: fbamba@haverford.edu | F39: Appliances | G39: Fridge | H39: Mid | I39: Black | J39: Avanti | K39: Great | L39: FALSE | M39: One Shelf
A40: 2022 | B40: 45163 | C40: Haitong Lian | D40: llian@haverford.edu | F40: Appliances | G40: Fridge - Freezer | H40: Cube | I40: Black | J40: Black and Decker | K40: Great | L40: FALSE | M40: Missing top Cap | One Shelf
...

Sheet Detailed Check-out
B1: Owner's Name | C1: Email | D1: Housing Assignment | E1: Graduation Year | F1: Items | G1: # of Items Checked Out | H1: Notes
A2: 45163 | B2: Ethan Rezer | C2: erezer@haverford.edu | D2: Gummere | E2: 2027 | F2: Rolling Storage Cart, Pencil Cup, Water Filter, Replacement Filter, Trash Can, Mini Fridge (44), Standing Lamp | G2: 7
A3: 45163 | B3: Lila Rivera | C3: larivera@haverford.edu | D3: North Dorms | E3: 2027 | F3: Bed Risers, Power Strip | G3: 2
A4: 45163 | B4: Charlene Frimpong | C4: cfrimpong@haverford.edu | D4: HCA | E4: 2026 | F4: Fake Plant, Calendar Whiteboard, Terrarium (On Hold Behind Desk), Sticker, Markers x3, staples, Notebook, Tea Kettle, Mirror, Tape, Pencil x2, Pen | G4: 16
A5: 45163 | B5: Trishia Phan | C5: tphan@haverford.edu | D5: HCA | E5: 2024 | F5: Microwave (No Photo) | G5: 1
A6: 45163 | B6: Citlali Camacho | C6: ccamacho@haverford.edu | D6: Kim/Tritton | E6: 2027 | F6: Mirror, Bed Risers, Hangers (x15), Cups (x3), Desk Lamp, Fan, Water Filter, Trash Can, Plates (x2), Forks (x2), Knives (x2), Spoons (x2), Binders (x2), Pencils (x8), Pens (x4), Clorox Wipes, Minifridge (14) , Laundry Detergent, Hamper, Decor, Storage (x2), Notebooks (x2), Alarm Clock, Shower Caddy, Bowls (x2), Power Strip, Toaster, Whiteboard, Shampoo, Conditioner, Facewash, Pinesol | G6: 66
A7: 45163 | B7: Angel Huitzil Huitzil | C7: ahuitzilhu@haverford.edu | D7: North Dorms | E7: 2027 | F7: Power Strip, Lamp, Minifridge (Insignia - 34 NTP), Trash Can, Lysol, Paper Towles, Clorox, Toilet Paper (x2), Hamper, Hangers (x5) | G7: 15
A8: 45163 | B8: Anita Lau | C8: alau@haverford.edu | D8: Kim/Tritton | E8: 2027 | F8: Fan, Trashcan, Mirror, Minifridge (53) | G8: 4
A9: 45163 | B9: Tinashe Mutasa | C9: tmutasa@haverford.edu | D9: BCC (Black Cultural Center) | E9: 2026 | F9: Minifridge (Whirlpool - Silver sticker on front 45), Water Filter | G9: 2
A10: 45163 | B10: Ghislaine Niyodusenga | C10: gniyodusen@haverford.edu | D10: North Dorms | E10: 2026 | F10: Minifridge (Midea - 7), Mirror, Bathroom Caddy, Toilet Paper, Lamp, Storage Bin, Plastic Bowls, and Cups, Hangers x 10) Power Strip | G10: 19
A11: 45163 | B11: Damião Victor Andrade da Silva | C11: dandradeda@haverford.edu | D11: North Dorms | E11: 2026 | F11: Minifridge (Kenmore - 16), Paper Towels, Mirror, Lamp, Trash Can, Flag, Hangers (x15), Plate, Cups (x2), Pencil Cup, Desktop Storage, Tap, Lysol, Fan, Water Filter | G11: 29
A12: 45163 | B12: Lucia Cortes | C12: lxcortes@haverford.edu | D12: Gummere | E12: 2027 | F12: Minifridge (Hi Sense), Lamp, Trash Can, Hangers (x12), Lysol Wipes (x2), Cups (x3), Mugs (x2), Mirror, Extension Cord, Plates (x2), Bowls (x2), Forks (x2), Mason Jar, Dust Pan, Carpe Diem, Tape, Cutting Board, Mirror, Hangers (x15), Iron, Tape, Basket | G12: 54
A13: 45163 | B13: Dakarai Lindsay | C13: dlindsay@haverford.edu | D13: Gummere | E13: 2027 | F13: Adorable giraffe and elephant lego, Bed Risers, Chalk Board, Extension Cord, Vines, Minifridge (Galanz - 42) | G13: 7
... A40: 45163 | B40: Uyen Tran | C40: utran@haverford.edu | D40: Gummere | E40: 2027 | F40: Minifridge (Magic Chef - 52), Trash Can, Fan, Lamp, Binder, Hangers (x9) | G40: 14
A41: 45163 | B41: Stephanie Lopez | C41: slopez1@haverford.edu | F41: Minifridge (Whirlpool), Mirror, Electric Kettle, Hangers (x2), Mini Clothespins | G41: 6
A42: 45163 | B42: Isabelle Setou | C42: isetou@haverford.edu | D42: North Dorms | E42: 2027 | F42: Hangers (x30) | G42: 30
A43: 45163 | B43: Isabela Jiménez | C43: ijimenez@haverford.edu | D43: Gummere | E43: 2027 | F43: Mirror w/ Hangers, Shower Caddy, Storage Bin, Drawer Liner, Minifridge (Whirlpool - 48) | G43: 5
A44: 45163 | B44: Leilani Davis | C44: lndavis@haverford.edu | D44: North Dorms | E44: 2027 | F44: Mirror, Minifridge (Galanz) | G44: 2
A45: 45163 | B45: Nicole Huang | C45: nhuang@haverford.edu | D45: Kim/Tritton | E45: 2027 | F45: Fan, Minifridge (Sunbeam) | G45: 2
A46: 45163 | B46: David Zeng | C46: dzeng@haverford.edu | D46: North Dorms | E46: 2027 | F46: Fan, Minifridge (Galanz), Mirror, Towel Bar, Flash Light, Desk Lamp, Portable Charger, Plastic Plates, Mug, Notecards, Filter (x2), Holepunch, Desktop Storage (x2), Spoon, Pen, Paper Clips, Clothes Pins (NOT PICTURED) | G46: 19
A47: 45163 | B47: Mustafa Elhassan | C47: melhassan@haverford.edu | D47: Kim/Tritton | E47: 2027 | F47: Minifridge (Haier - 2), Bed Risers, Lamp, Hangers (x10), Fan, Trash Can (NOT PICTURED) | G47: 15
A48: 45163 | B48: Mischelly Low | C48: mlow | D48: HCA | E48: 2025 | F48: Lamp, Iceskates, Rice Cooker, Brita, Wet Wipes, Shower Hnager, Kleenex, Mini Towels, Dish Rack, Tape, Pencils (x5), Pen | G48: 16
A49: 45163 | B49: Eugene Yang | C49: eyyang@haverford.edu | D49: Lloyd | E49: 2024 | F49: Minifridge (SPT 35) | G49: 1
A50: 45163 | B50: Deep Patel | C50: dcpatel@haverford.edu | D50: Lloyd | E50: 2025 | F50: Frisbee, Pull up Bar, Paper Roll | G50: 3
A51: 45163 | B51: Ana Isabela Azumatan Aceituno | C51: iazumatana@haverford.edu | D51: Gummere | E51: 2027 | F51: Minifridge (Frigidare - 37), Umbrella, Brita, Fan, Lamp | G51: 5
A52: 45163 | B52: Hazel Alvarado | C52: halvarado@haverford.edu | D52: North Dorms | E52: 2027 | F52: Minifridge (Euhomy), Lanudry Basket, Trah Can, Desk Lamp, Bed Risers, Humidifier, Tiny AC, Tape, Pencil Cup, Destop Storage, Binder, Folder, Ruler, Glue, Hangers (x15), Eraser, Pencils (x3), Glue Stick, Calculator, Mirror | G52: 36
A53: 45163 | B53: Andrea Recinos-Manchame | C53: arecinosma@haverford.edu | D53: Gummere | E53: 2027 | F53: Minifridge (Frigidare - 8), Mirror, Desktop Lamp, Hangers (x8), | G53: 11
... A119: 45166 | B119: Citlali Camacho | C119: ccamacho@haverford.edu | D119: Kim/Tritton | E119: 2027 | F119: Storage Bin, Paper Clips, Colored Pencils, Ruler, Stapler, Notecards, Pencils (x8), Expo Markers (x2), Paper, Hole Punch, Binder | G119: 19
A120: 45166 | B120: Boahen Kwake | D120: HCA | E120: 2024 | F120: Dish Soap, Gloves, Sponge, Extension Cord (No Photo Of this Order) | G120: 4
A121: 45166 | B121: Pritha Aryal | C121: paryal@haverford.edu | D121: HCA | E121: 2024 | F121: Mug, Cheese Grater, Bowl, Fryer, Shot Glasses (x4), Wine Glass (x2), Mug, Shaker, Can Opener, Desk Lamp, Cutting Board, Egglplant Dish, Candle Holder, Hot Pad (x2), Cork Coaster, Decor, Cordial Glasses (x4), Jade Roller, Plant (x2), Trash Can | G121: 29
A122: 45166 | B122: Rupert Lim | C122: rlim1@haverford.edu | D122: Kim/Tritton | E122: 2027 | F122: Desk Lamp, Markers (x3), Suction Cups (x2), Wipes, Tape, Colored Pencils, Notebooks (x2) | G122: 11
A123: 45166 | B123: Haitong Lian | C123: llian@haverford.edu | D123: North Dorms | E123: 2027 | F123: Tape, Pens (x3), Wipes, Suction Cup, Post Its, Hand Sanitizer | G123: 8
A124: 45166 | B124: Anuj Poddar | C124: apoddar@haverford.edu | D124: North Dorms | E124: 2027 | F124: Trash Can, Fan | G124: 2
A125: 45166 | B125: Ziyin Zhang | C125: zzhang6@haverford.edu | D125: Kim/Tritton | E125: 2027 | F125: Hangers (x7), Lamp, Trash Can, Storage Bin (Have Photo just debating name) | G125: 10
A126: 45166 | B126: Yasmin Silva Nillson | C126: ysilvanils@haverford.edu | D126: Kim/Tritton | E126: 2026 | F126: Minifrdige (Sunbeam), Bed Risers, Trash Can, Books (x4), Hangers (x5), Mirror | G126: 13
A127: 45166 | B127: Jacob Foster | C127: jfoster@haverford.edu | D127: Yarnall | E127: 2024 | F127: Cork Board, Tape (x2), Toothbrushes (x2), Stickers, Ruler, Sensu Fans (x5), Embroidery Thread, Tacs, Clothespins (x5), Binder Clips, Paper Clips, Folder, Plants (x2) | G127: 24
A128: 45166 | B128: Julia Knihs | C128: jknihs@haverford.edu | D128: HCA | E128: 2025 | F128: Dory Coloring Book | G128: 1
A129: 45166 | B129: Elena Bien | C129: ebien@haverford.edu | D129: Leeds | E129: 2024 | F129: Mirror, Bed Risers, Tape (x2), Hangers (x4), Mugs (x2), Post It Notes, Ziplocs, Minifridge (Insignia) | G129: 13
A130: 45166 | B130: Ali Gulamhusein | C130: agulamhuse@haverford.edu | D130: Kim/Tritton | E130: 2027 | F130: Computation Notebook, Hangers (x5), Roledex, Book, Board Games (x2), HDMI Cords (x5), Desk Lamp, Minifridge (Haier), Thermometer, bandaids | G130: 17
A131: 45166 | B131: Eustace Ubah | C131: eubah@haverford.edu | D131: North Dorms | E131: 2027 | F131: Minifridge (Sunbeam), Trash Can | G131: 2
...

Sheet Waitlist
A1: Date | B1: Requestor | C1: Email | D1: Housing Assignment | E1: Graduation Year | F1: Minifridge | G1: Lamp | H1: Fan | I1: Trashcan | J1: Other
B2: Michelley Low | F2: FALSE | G2: FALSE | H2: FALSE | I2: TRUE
B3: Dan Adamopulos | C3: dadamopulo@haverford.edu | D3: Gummere | E3: 2026 | F3: FALSE | G3: FALSE | H3: TRUE | I3: FALSE
B4: Aida Standerford | C4: astanderfo@haverford.edu | D4: Gummere | E4: 2027 | F4: FALSE | G4: FALSE | H4: FALSE | I4: TRUE
B5: Mateo Kietzman | C5: mkietzman@haverford.edu | D5: North Dorms | E5: 2027 | F5: FALSE | G5: FALSE | H5: FALSE | I5: TRUE
B6: Chantelle Mawoneke | F6: FALSE | G6: FALSE | H6: TRUE | I6: FALSE
B7: Nayera Hasan | F7: FALSE | G7: FALSE | H7: FALSE | I7: TRUE
B8: Kaiya Inouye | C8: kinouye@haverford.edu | D8: Gummere | E8: 2027 | F8: TRUE | G8: FALSE | H8: FALSE | I8: FALSE
B9: Lauren Petrilla | C9: lpetrilla@haverford.edu | D9: North Dorms | E9: 2027 | F9: TRUE | G9: FALSE | H9: FALSE | I9: FALSE
B10: Grace Chen | C10: gtchen@haverford.edu | D10: North Dorms | E10: 2027 | F10: TRUE | G10: FALSE | H10: FALSE | I10: FALSE
B11: Masa Hasegawa | C11: mhasegawa@haverford.edu | D11: HCA | E11: 2026 | F11: FALSE | G11: FALSE | H11: FALSE | I11: FALSE | J11: Blender
B12: Sarah Wilcher | F12: TRUE | G12: FALSE | H12: FALSE | I12: FALSE
B13: Reesha Gandhi | D13: Leeds | E13: 2024 | F13: TRUE | G13: FALSE | H13: FALSE | I13: FALSE
B14: Jiahan (Nicole) Li | F14: TRUE | G14: FALSE | H14: FALSE | I14: FALSE
B15: Gabe Franklin | C15: gfranklin | F15: TRUE | G15: FALSE | H15: FALSE | I15: FALSE
A16: 45181 | B16: Tova Gordon | C16: tgordon@haverford.edu | D16: North Dorms | E16: 2027 | F16: TRUE | G16: FALSE | H16: FALSE | I16: FALSE
F17: FALSE | G17: FALSE | H17: FALSE | I17: FALSE
F18: FALSE | G18: FALSE | H18: FALSE | I18: FALSE
F19: FALSE | G19: FALSE | H19: FALSE | I19: FALSE
F20: FALSE | G20: FALSE | H20: FALSE | I20: FALSE
F21: FALSE | G21: FALSE | H21: FALSE | I21: FALSE
F22: FALSE | G22: FALSE | H22: FALSE | I22: FALSE
F23: FALSE | G23: FALSE | H23: FALSE | I23: FALSE
F24: FALSE | G24: FALSE | H24: FALSE | I24: FALSE
F25: FALSE | G25: FALSE | H25: FALSE | I25: FALSE
F26: FALSE | G26: FALSE | H26: FALSE | I26: FALSE
F27: FALSE | G27: FALSE | H27: FALSE | I27: FALSE
F28: FALSE | G28: FALSE | H28: FALSE | I28: FALSE
... F41: FALSE | G41: FALSE | H41: FALSE | I41: FALSE
F42: =countif(F2:F43,true) -> 8 | G42: =countif(G2:G43,true) -> 0 | H42: =countif(H2:H43,true) -> 2 | I42: =countif(I2:I43,true) -> 4

Sheet Parameters
A1: Sheet | B1: Reference header | C1: Column
A2: Check-in | B2: Check-in date | C2: =IF(B2="","",LEFT(ADDRESS(1,MATCH(B2,INDIRECT("'"&A2&"'!$1:$1"),FALSE),4))) -> #N/A
A3: Check-in | B3: Quantity | C3: =IF(B3="","",LEFT(ADDRESS(1,MATCH(B3,INDIRECT("'"&A3&"'!$1:$1"),FALSE),4))) -> D
A4: Check-out | B4: Check-out date | C4: =IF(B4="","",LEFT(ADDRESS(1,MATCH(B4,INDIRECT("'"&A4&"'!$1:$1"),FALSE),4))) -> A
A5: Check-out | B5: Quantity | C5: =IF(B5="","",LEFT(ADDRESS(1,MATCH(B5,INDIRECT("'"&A5&"'!$1:$1"),FALSE),4))) -> D
A6: Current inventory list | B6: ='Current inventory list'!B1 -> Item name | C6: =IF(B6="","",LEFT(ADDRESS(1,MATCH(B6,INDIRECT("'"&A6&"'!$1:$1"),FALSE),4))) -> B
A7: Current inventory list | B7: ='Current inventory list'!D1 -> Check-in total | C7: =IF(B7="","",LEFT(ADDRESS(1,MATCH(B7,INDIRECT("'"&A7&"'!$1:$1"),FALSE),4))) -> D
C8: =IF(B8="","",LEFT(ADDRESS(1,MATCH(B8,INDIRECT("'"&A8&"'!$1:$1"),FALSE),4)))
C9: =IF(B9="","",LEFT(ADDRESS(1,MATCH(B9,INDIRECT("'"&A9&"'!$1:$1"),FALSE),4)))
C10: =IF(B10="","",LEFT(ADDRESS(1,MATCH(B10,INDIRECT("'"&A10&"'!$1:$1"),FALSE),4)))
C11: =IF(B11="","",LEFT(ADDRESS(1,MATCH(B11,INDIRECT("'"&A11&"'!$1:$1"),FALSE),4)))
C12: =IF(B12="","",LEFT(ADDRESS(1,MATCH(B12,INDIRECT("'"&A12&"'!$1:$1"),FALSE),4)))
C13: =IF(B13="","",LEFT(ADDRESS(1,MATCH(B13,INDIRECT("'"&A13&"'!$1:$1"),FALSE),4)))
C14: =IF(B14="","",LEFT(ADDRESS(1,MATCH(B14,INDIRECT("'"&A14&"'!$1:$1"),FALSE),4)))
C15: =IF(B15="","",LEFT(ADDRESS(1,MATCH(B15,INDIRECT("'"&A15&"'!$1:$1"),FALSE),4)))

Sheet Data preparation (Week analysis
A1: =IFERROR(__xludf.DUMMYFUNCTION("QUERY('Check-out'!A:Z,""SELECT ""&Parameters!C4&"",SUM(""&Parameters!C5&"") WHERE ""&Parameters!C5&"">0 GROUP BY ""&Parameters!C4&"" LABEL SUM(""&Parameters!C5&"") 'Total quantity'"")"),"Check-out date") -> Check-out date | B1: =IFERROR(__xludf.DUMMYFUNCTION("""COMPUTED_VALUE"""),"Total quantity") -> Total quantity | C1: {=IF(ROW(A1:A1001)=1,"Weekday",IF(A1:A1001="","",CHOOSE(WEEKDAY(A1:A1001,2),"Monday","Tuesday","Wednesday","Thursday","Friday","Saturday","Sunday")))} -> Weekday | D1: Weekday | E1: Average quantity
B2: =IFERROR(__xludf.DUMMYFUNCTION("""COMPUTED_VALUE"""),1.0) -> 1 | D2: Monday | E2: =AVERAGEIF(C:C,D2,B:B) -> #DIV/0!
D3: Tuesday | E3: =AVERAGEIF(C:C,D3,B:B) -> #DIV/0!
D4: Wednesday | E4: =AVERAGEIF(C:C,D4,B:B) -> #DIV/0!
D5: Thursday | E5: =AVERAGEIF(C:C,D5,B:B) -> #DIV/0!
D6: Friday | E6: =AVERAGEIF(C:C,D6,B:B) -> #DIV/0!
D7: Saturday | E7: =AVERAGEIF(C:C,D7,B:B) -> #DIV/0!
D8: Sunday | E8: =AVERAGEIF(C:C,D8,B:B) -> #DIV/0!

Sheet Data preparation (Last 15 days)
A1: Last 15 days | B1: In | C1: Out
A2: =A3-1 -> 44794 | B2: {=SUMIF(INDIRECT("'Check-in'!"&Parameters!C$2&":"&Parameters!C$2&""),A2,INDIRECT("'Check-in'!"&Parameters!C$3&":"&Parameters!C$3&""))} -> 0 | C2: {=SUMIF(INDIRECT("'Check-out'!"&Parameters!C$4&":"&Parameters!C$4&""),A2,INDIRECT("'Check-out'!"&Parameters!C$5&":"&Parameters!C$5&""))} -> 0
A3: =A4-1 -> 44795 | B3: {=SUMIF(INDIRECT("'Check-in'!"&Parameters!C$2&":"&Parameters!C$2&""),A3,INDIRECT("'Check-in'!"&Parameters!C$3&":"&Parameters!C$3&""))} -> 0 | C3: {=SUMIF(INDIRECT("'Check-out'!"&Parameters!C$4&":"&Parameters!C$4&""),A3,INDIRECT("'Check-out'!"&Parameters!C$5&":"&Parameters!C$5&""))} -> 0
A4: =A5-1 -> 44796 | B4: {=SUMIF(INDIRECT("'Check-in'!"&Parameters!C$2&":"&Parameters!C$2&""),A4,INDIRECT("'Check-in'!"&Parameters!C$3&":"&Parameters!C$3&""))} -> 0 | C4: {=SUMIF(INDIRECT("'Check-out'!"&Parameters!C$4&":"&Parameters!C$4&""),A4,INDIRECT("'Check-out'!"&Parameters!C$5&":"&Parameters!C$5&""))} -> 0
A5: =A6-1 -> 44797 | B5: {=SUMIF(INDIRECT("'Check-in'!"&Parameters!C$2&":"&Parameters!C$2&""),A5,INDIRECT("'Check-in'!"&Parameters!C$3&":"&Parameters!C$3&""))} -> 0 | C5: {=SUMIF(INDIRECT("'Check-out'!"&Parameters!C$4&":"&Parameters!C$4&""),A5,INDIRECT("'Check-out'!"&Parameters!C$5&":"&Parameters!C$5&""))} -> 0
A6: =A7-1 -> 44798 | B6: {=SUMIF(INDIRECT("'Check-in'!"&Parameters!C$2&":"&Parameters!C$2&""),A6,INDIRECT("'Check-in'!"&Parameters!C$3&":"&Parameters!C$3&""))} -> 0 | C6: {=SUMIF(INDIRECT("'Check-out'!"&Parameters!C$4&":"&Parameters!C$4&""),A6,INDIRECT("'Check-out'!"&Parameters!C$5&":"&Parameters!C$5&""))} -> 0
A7: =A8-1 -> 44799 | B7: {=SUMIF(INDIRECT("'Check-in'!"&Parameters!C$2&":"&Parameters!C$2&""),A7,INDIRECT("'Check-in'!"&Parameters!C$3&":"&Parameters!C$3&""))} -> 0 | C7: {=SUMIF(INDIRECT("'Check-out'!"&Parameters!C$4&":"&Parameters!C$4&""),A7,INDIRECT("'Check-out'!"&Parameters!C$5&":"&Parameters!C$5&""))} -> 0
A8: =A9-1 -> 44800 | B8: {=SUMIF(INDIRECT("'Check-in'!"&Parameters!C$2&":"&Parameters!C$2&""),A8,INDIRECT("'Check-in'!"&Parameters!C$3&":"&Parameters!C$3&""))} -> 0 | C8: {=SUMIF(INDIRECT("'Check-out'!"&Parameters!C$4&":"&Parameters!C$4&""),A8,INDIRECT("'Check-out'!"&Parameters!C$5&":"&Parameters!C$5&""))} -> 0
A9: =A10-1 -> 44801 | B9: {=SUMIF(INDIRECT("'Check-in'!"&Parameters!C$2&":"&Parameters!C$2&""),A9,INDIRECT("'Check-in'!"&Parameters!C$3&":"&Parameters!C$3&""))} -> 0 | C9: {=SUMIF(INDIRECT("'Check-out'!"&Parameters!C$4&":"&Parameters!C$4&""),A9,INDIRECT("'Check-out'!"&Parameters!C$5&":"&Parameters!C$5&""))} -> 0
A10: =A11-1 -> 44802 | B10: {=SUMIF(INDIRECT("'Check-in'!"&Parameters!C$2&":"&Parameters!C$2&""),A10,INDIRECT("'Check-in'!"&Parameters!C$3&":"&Parameters!C$3&""))} -> 0 | C10: {=SUMIF(INDIRECT("'Check-out'!"&Parameters!C$4&":"&Parameters!C$4&""),A10,INDIRECT("'Check-out'!"&Parameters!C$5&":"&Parameters!C$5&""))} -> 0
A11: =A12-1 -> 44803 | B11: {=SUMIF(INDIRECT("'Check-in'!"&Parameters!C$2&":"&Parameters!C$2&""),A11,INDIRECT("'Check-in'!"&Parameters!C$3&":"&Parameters!C$3&""))} -> 0 | C11: {=SUMIF(INDIRECT("'Check-out'!"&Parameters!C$4&":"&Parameters!C$4&""),A11,INDIRECT("'Check-out'!"&Parameters!C$5&":"&Parameters!C$5&""))} -> 0
A12: =A13-1 -> 44804 | B12: {=SUMIF(INDIRECT("'Check-in'!"&Parameters!C$2&":"&Parameters!C$2&""),A12,INDIRECT("'Check-in'!"&Parameters!C$3&":"&Parameters!C$3&""))} -> 0 | C12: {=SUMIF(INDIRECT("'Check-out'!"&Parameters!C$4&":"&Parameters!C$4&""),A12,INDIRECT("'Check-out'!"&Parameters!C$5&":"&Parameters!C$5&""))} -> 0
A13: =A14-1 -> 44805 | B13: {=SUMIF(INDIRECT("'Check-in'!"&Parameters!C$2&":"&Parameters!C$2&""),A13,INDIRECT("'Check-in'!"&Parameters!C$3&":"&Parameters!C$3&""))} -> 0 | C13: {=SUMIF(INDIRECT("'Check-out'!"&Parameters!C$4&":"&Parameters!C$4&""),A13,INDIRECT("'Check-out'!"&Parameters!C$5&":"&Parameters!C$5&""))} -> 0
... A15: =A16-1 -> 44807 | B15: {=SUMIF(INDIRECT("'Check-in'!"&Parameters!C$2&":"&Parameters!C$2&""),A15,INDIRECT("'Check-in'!"&Parameters!C$3&":"&Parameters!C$3&""))} -> 0 | C15: {=SUMIF(INDIRECT("'Check-out'!"&Parameters!C$4&":"&Parameters!C$4&""),A15,INDIRECT("'Check-out'!"&Parameters!C$5&":"&Parameters!C$5&""))} -> 0
A16: =MAX('Check-out'!A2:A998) -> 44808 | B16: {=SUMIF(INDIRECT("'Check-in'!"&Parameters!C$2&":"&Parameters!C$2&""),A16,INDIRECT("'Check-in'!"&Parameters!C$3&":"&Parameters!C$3&""))} -> 0 | C16: {=SUMIF(INDIRECT("'Check-out'!"&Parameters!C$4&":"&Parameters!C$4&""),A16,INDIRECT("'Check-out'!"&Parameters!C$5&":"&Parameters!C$5&""))} -> 0

Sheet Data preparation (Over sold ite
A1: Over sold items | E1: DIFF
A2: =IFERROR(__xludf.DUMMYFUNCTION("IFERROR(QUERY('Current inventory list'!A2:G15,""SELECT B WHERE F<0 LIMIT 9"",0),""None"")"),"Party Games") -> Party Games | E2: =IFERROR(__xludf.DUMMYFUNCTION("IFERROR(QUERY('Current inventory list'!A2:G15,""SELECT F WHERE F<0 LIMIT 9"",0),""None"")"),-1.0) -> -1
