Workbook
Name totalItemsInStock: Dashboard!$H$4

Sheet Check-out
A1: Check-out date | B1: Stock keeping unit (SKU) | C1: {=IF(ROW(A1:A992)=1,"Item name (automatic fill)",IF(B1:B992="","",VLOOKUP(B1:B992,'Check-in'!B:C,2,FALSE)))} -> Item name (automatic fill) | D1: Quantity | E1: {=IF(ROW(A1:A992)=1,"Unit of measure (automatic fill)",IF(B1:B992="","",VLOOKUP(B1:B992,'Check-in'!B:E,4,FALSE)))} -> Unit of measure (automatic fill)
B2: KIBA | C2: Barware | D2: 1 | E2: unit

Sheet Check-in
A1: Date | B1: Stock keeping unit (SKU) | C1: Item name | D1: Quantity | E1: Unit of measure
B2: BAAF | C2: Air Freshener | E2: unit
B3: ELAC | C3: Alarm Clocks | E3: unit
B4: BAAS | C4: Alcohol Swabs/Lens Wipes | E4: unit
B5: KIAF | C5: Aluminum Foil | E5: unit
B6: BAAN | C6: Antiseptic | E6: unit
B7: BABP | C7: Baby Powder | E7: unit
B8: KIBP | C8: Baking Pans | E8: unit
B9: BABA | C9: Band-Aids | E9: unit
B10: KIBA | C10: Barware | E10: unit
B11: LABA | C11: Baskets | E11: unit
B12: ARBE | C12: Beads | E12: unit
B13: FUBR | C13: Bed Risers | E13: unit
... B246: KIZI | C246: Ziplocs | E246: unit

Sheet Dashboard
H3: TOTAL ITEMS IN STOCK | P3: SOLD OUT ITEMS
H4: =SUM('Current inventory list'!F2:F28) -> -1 | P4: =IFERROR(__xludf.DUMMYFUNCTION("IFERROR(QUERY('Current inventory list'!A2:G28,""SELECT B WHERE F=0 LIMIT 9"",0),""None"")"),"Air Freshener") -> Air Freshener
P5: =IFERROR(__xludf.DUMMYFUNCTION("""COMPUTED_VALUE"""),"Alarm Clocks") -> Alarm Clocks
P6: =IFERROR(__xludf.DUMMYFUNCTION("""COMPUTED_VALUE"""),"Alcohol Swabs/Lens Wipes") -> Alcohol Swabs/Lens Wipes
P7: =IFERROR(__xludf.DUMMYFUNCTION("""COMPUTED_VALUE"""),"Aluminum Foil") -> Aluminum Foil
B8: Inventory management | H8: TOP ITEMS | P8: =IFERROR(__xludf.DUMMYFUNCTION("""COMPUTED_VALUE"""),"Antiseptic") -> Antiseptic
E9: by | H9: IN | I9: =IFERROR(__xludf.DUMMYFUNCTION("QUERY('Current inventory list'!A2:G28,""SELECT B ORDER BY D DESC LIMIT 1"",0)"),"Air Freshener") -> Air Freshener | P9: =IFERROR(__xludf.DUMMYFUNCTION("""COMPUTED_VALUE"""),"Baby Powder") -> Baby Powder
P10: =IFERROR(__xludf.DUMMYFUNCTION("""COMPUTED_VALUE"""),"Baking Pans") -> Baking Pans
H11: OUT | I11: =IFERROR(__xludf.DUMMYFUNCTION("QUERY('Current inventory list'!A10:G28,""SELECT B ORDER BY E DESC LIMIT 1"",0)"),"Barware") -> Barware | P11: =IFERROR(__xludf.DUMMYFUNCTION("""COMPUTED_VALUE"""),"Band-Aids") -> Band-Aids
P12: =IFERROR(__xludf.DUMMYFUNCTION("""COMPUTED_VALUE"""),"Baskets") -> Baskets

Sheet Current inventory list
A1: {=UNIQUE(INDIRECT("'Check-in'!"&LEFT(ADDRESS(1,MATCH("Stock Keeping Unit (SKU)",'Check-in'!1:1,FALSE),4,TRUE))&":"&LEFT(ADDRESS(1,MATCH("Stock Keeping Unit (SKU)",'Check-in'!1:1,FALSE),4,TRUE))&""))} -> Stock keeping unit (SKU) | B1: Item name | C1: Unit of measure | D1: {=IF(ROW(A1:A1000)=1,"Check-in total",IF(A1:A1000="","",SUMIF(INDIRECT("'Check-in'!"&LEFT(ADDRESS(1,MATCH("Stock keeping unit (SKU)",'Check-in'!1:1,FALSE),4,TRUE))&":"&LEFT(ADDRESS(1,MATCH("Stock keeping unit (SKU)",'Check-in'!1:1,FALSE),4,TRUE))&""),A1:A1000,INDIRECT("'Check-in'!"&LEFT(ADDRESS(1,MATCH("Quantity",'Check-in'!1:1,FALSE),4,TRUE))&":"&LEFT(ADDRESS(1,MATCH("Quantity",'Check-in'!1:1,FALSE),4,TRUE))&""))))} -> Check-in total | E1: {=IF(ROW(A1:A1000)=1,"Check-out total",IF(A1:A1000="","",SUMIF(INDIRECT("'Check-out'!"&LEFT(ADDRESS(1,MATCH("Stock keeping unit (SKU)",'Check-out'!1:1,FALSE),4,TRUE))&":"&LEFT(ADDRESS(1,MATCH("Stock keeping unit (SKU)",'Check-out'!1:1,FALSE),4,TRUE))&""),A1:A1000,INDIRECT("'Check-out'!"&LEFT(ADDRESS(1,MATCH("Quantity",'Check-out'!1:1,FALSE),4,TRUE))&":"&LEFT(ADDRESS(1,MATCH("Quantity",'Check-out'!1:1,FALSE),4,TRUE))&""))))} -> Check-out total | F1: {=IF(ROW(A1:A1000)=1,"Inventory",IF(A1:A1000="","",(D1:D1000-E1:E1000)))} -> Inventory | G1: {=IF(ROW(A1:A1000)=1,"% Available",IFERROR(IF(F1:F1000="","",F1:F1000/D1:D1000),0))} -> % Available
A2: BAAF | B2: Air Freshener | C2: unit | D2: 0 | E2: 0 | F2: 0 | G2: 0
A3: ELAC | B3: Alarm Clocks | C3: unit | D3: 0 | E3: 0 | F3: 0 | G3: 0
A4: BAAS | B4: Alcohol Swabs/Lens Wipes | C4: unit | D4: 0 | E4: 0 | F4: 0 | G4: 0
A5: KIAF | B5: Aluminum Foil | C5: unit | D5: 0 | E5: 0 | F5: 0 | G5: 0
A6: BAAN | B6: Antiseptic | C6: unit | D6: 0 | E6: 0 | F6: 0 | G6: 0
A7: BABP | B7: Baby Powder | C7: unit | D7: 0 | E7: 0 | F7: 0 | G7: 0
A8: KIBP | B8: Baking Pans | C8: unit | D8: 0 | E8: 0 | F8: 0 | G8: 0
A9: BABA | B9: Band-Aids | C9: unit | D9: 0 | E9: 0 | F9: 0 | G9: 0
A10: KIBA | B10: Barware | C10: unit | D10: 0 | E10: 1 | F10: -1 | G10: 0
A11: LABA | B11: Baskets | C11: unit | D11: 0 | E11: 0 | F11: 0 | G11: 0
A12: ARBE | B12: Beads | C12: unit | D12: 0 | E12: 0 | F12: 0 | G12: 0
A13: FUBR | B13: Bed Risers | C13: unit | D13: 0 | E13: 0 | F13: 0 | G13: 0
... A240: KIZI | B240: Ziplocs | C240: unit | D240: 0 | E240: 0 | F240: 0 | G240: 0

Sheet Detailed Check-out
A1: Date | B1: Owner's Name | C1: Email | D1: Housing Assignment | E1: Graduation Year | F1: Items | G1: # of Items Checked Out | H1: Notes
A2: 45804 | B2: Isabelle Szeto | C2: iszeto@haverford.edu | D2: HCA | E2: 2027 | F2: Trash can, extension cord, yoga mat, chargers, soap, bottle of cleaner | G2: 7
A3: 45804 | B3: Yuko Zhuo | C3: yzhuo1@haverford.edu | D3: HCA | E3: 2027 | F3: Stool, yoga mat, mirror, swiffer, trash can, games (2), mirror hangers (2) | G3: 9
A4: 45804 | B4: Fabian Castro | C4: fcastro@haverford.edu | D4: HCA | E4: 2026 | F4: Toaster, container, Pans (2), skillets (2), lid, measuring cup, dishrack, cleaner (2), spatula(2), wooden spoon, knife, baking pan | G4: 16
A5: 45804 | B5: Santos Diaz | C5: sdiaz@haverford.edu | D5: HCA | E5: 2025 | F5: Toaster, broom, vase, trash can, lamp, baking tray, plates (7), pot with lid, mug (3), strainer, cups (3), trash bags, container, brita, febreeze, water bottle, spatula, spoon (6), forks (4), butterknives (2), sponges (3), plant, knife, art, games (2), umbrellas (2), condoms (6), books (6), string lights | G5: 54
A6: 45804 | B6: Anna Martinez | C6: amartinez2@haverford.edu | D6: HCA | E6: 2026 | F6: Pans (2), Plate, Ice cube tray, Brush, dry erase (3), sharpies(3), Pads (3), cleaner, Mop cleaner, Spoons (3), forks (2), tongs, Knives (2), trash can, measuring cup, post-its, swiffer wet cloth, mirror | G6: 29
A7: 45804 | B7: Majdouline Benlahcen | C7: mbenlahcen@haverford.edu | D7: HCA | E7: 2027 | F7: Game(2), scale, Shoe rack, HCI acid maker, File folder, mirror, trash can, shower organizer, lamp (2), fake plant, french press, planters (2), magnet, baking soda, storage containers (3), hardware kit, calculator, storage bin (2) carpet cleaner, toilet cleaner, power strips (2), soap, laundry basket | G7: 30
A8: 45804 | B8: Fatoumata Barry | C8: fbarry@haverford.edu | D8: HCA | E8: 2026 | F8: Mirror, trash can, pan, tennis ball, forks (2), sponge, spoon, spatula, knives (2) trash bags, bathroom cleaner | G8: 13
A9: 45804 | B9: Max Negbaur | C9: mnegbaur@haverford.edu | D9: HCA | E9: 2028 | F9: Tupperware (4), butterknives(2), paper, mirror, markers (3) | G9: 8
A10: 45804 | B10: Fatoumata Sow | C10: fsow@haverford.edu | D10: HCA | E10: 2027 | F10: paper towel, sanitizer (2), wipes, air purifier, bleach, swiffer dust pads, cleaner, soap, mist, command hook | G10: 11
A11: 45804 | B11: David Punyataweekul | C11: dpunyatawe@haverford.edu | D11: HCA | E11: 2027 | F11: Power Strip, Chalk, Robot Car Kit and Accessory | G11: 4
A12: 45804 | B12: Eustace Ubah | C12: eubah@haverford.edu | D12: HCA | E12: 2027 | F12: Power Strip | G12: 1
A13: 45804 | B13: Santos Diaz | C13: sdiaz@haverford.edu | D13: HCA | E13: 2025 | F13: Lamp, Pan | G13: 2
... A66: 45804 | B66: Mohammed Fanous | C66: mfanous@haverford.edu | D66: HCA | E66: 2025 | F66: TV, hangers (15), Fake Candelabras (2) String lights (3), fake leaves (2), Art (4), Trashcans (2), Bowl, Plates (2) | G66: 32
A67: 45812 | B67: Angie Merriken and Mitch Roberge | C67: amerriken@haverford.edu | D67: Staff/Faculty Office | E67: Staff | F67: Toaster, Pencil Sharpener, Wall File Folders (2), Fan, Desk lamp, Clipboard, Binder, Colored Pencils (x2), Highlighters (x2), Expo Markers (x4), Command Hooks (x4), Command Stickers (x10), Tape (x2) | G67: 32
A68: 45891 | B68: Maya Rodenbeck | C68: mrodenbeck@haverford.edu | D68: North Dorms | E68: 2028 | F68: Hangers (x25), Minifridge (#33), Tape | G68: 27
A69: 45891 | B69: Lazaro Villasana | C69: lvillasana@haverford.edu | D69: Barclay | E69: 2029 | F69: Minifridge (#228), Lamp, Vacuum, Scale, Power Strip, Yoga Mat, Jenga, Corkboard | G69: 8
A70: 45891 | B70: Felipe Christ | C70: fchrist@haverford.edu | D70: Barclay | E70: 2029 | F70: Minifridge (#203), Fan, Vacuum, Printer, Keyboard, Printer Ink, Trash Bags, Hangers (x15), Lamp, Power Strip, Extension Cord, Flashlight, Air Fryer, Ipad | G70: 28
A71: 45891 | B71: Ivan Paiewonsky | C71: ipaiewonsk@haverford.edu | D71: Kim/Tritton | E71: 2028 | F71: Shower Caddy, Pens (x3), Water Guns (x2) | G71: 6
A72: 45891 | B72: Jihoo Kim | C72: jkim17@haverford.edu | D72: Leeds | E72: 2028 | F72: Cleaner, Minifridge (#219) | G72: 2
A73: 45891 | B73: Garrett Miyagawa | C73: gmiyagawa@haverford.edu | D73: North Dorms | E73: 2029 | F73: Minifridge (#205), Lamp, Storage Bins (x3), Tennis Balls (x3), Pedals, Shower Caddy, Tape (x2), Bed Risers, Jar, Shoe Mat, Storage | G73: 16
A74: 45891 | B74: Wayne Hsu | C74: whsu1@haverford.edu | D74: Gummere | E74: 2029 | F74: Shower Caddy, Lamp, Hangers (x3), Fan, Trash Can, Power Strips (x2), Shelf, Minifridge (#157) | G74: 11
A75: 45891 | B75: Ricardo Martinez | C75: rmartinez@haverford.edu | D75: North Dorms | E75: 2029 | F75: Extension Cord, Minifridge (#225) | G75: 2
A76: 45891 | B76: Mariia Dmitrieva | C76: mdmitrieva@haverford.edu | D76: Gummere | E76: 2029 | F76: Lamp, Fan, Humidifier, Lights, Desktop Storage, Hangers (x10), Mirror, Cart, Lamp, Minifridge (#221), Storage Boxes (x4), Calculator | G76: 24
A77: 45891 | B77: José Wagner Paixão dos Santos | C77: jpaixaodos@haverford.edu | D77: Gummere | E77: 2029 | F77: Lamp, Desktop Storage, Humidifier, Minifridge (#127), Ice Cube Tray, Storage (x2), Shelf, Fan | G77: 9
A78: 45891 | B78: Marlen Becerril | C78: mbecerril@haverford.edu | D78: Kim/Tritton | E78: 2029 | F78: Minifridge (#102), Ice Cube Trays (x2) | G78: 3
A79: 45891 | B79: Rameel Rizwan | C79: rrizwan@haverford.edu | D79: Barclay | E79: 2029 | F79: Rolling Storage, Hangers (10), Power Strip, Trash Can, Charging Port, Minifridge (#211), Standing Lamp | G79: 16
... A196: 45894 | B196: AJ Abdurakhimov | C196: aavdurkahi@haverford.edu | D196: Barclay | E196: 2029 | F196: Detergent, Rolling Cart, Laundry Basket (NOT PICTURED) | G196: 3
A197: 8/25/0225 | B197: Eliana Kim | C197: eykim@haverford.edu | D197: North Dorms | E197: 2028 | F197: Mirror, Trash Can | G197: 2
A198: 45894 | B198: Sandy Xu | C198: swxu@haverford.edu | D198: Kim/Tritton | E198: 2029 | F198: Rolling Cart, Desktop Storage, Whiteboard | G198: 3
A199: 45894 | B199: Jean Paulino | C199: jpaulino@haverford.edu | D199: Gummere | E199: 2029 | F199: Minifridge (#206) | G199: 1
A200: 45894 | B200: Muhammad Bashir | C200: mbashir@haverford.edu | D200: Barclay | E200: 2029 | F200: Standing Lamp, Trash Can, Vase | G200: 3
A201: 45894 | B201: Sho Nadata | C201: snadata@haverford.edu | D201: Barclay | E201: 2029 | F201: Bin, Umbrealla, Soccer Ball, Tape, Eraser, Sharpener, Pencils (x5), Pens (x2), Scissors, Pencil Case, Power Strip, Yoga Mat, Notebooks (x5), Folders (x3), Cleats, Trash Can | G201: 27
A202: 45894 | B202: Grace Leverton | C202: gleverton@haverford.edu | D202: Kim/Tritton | E202: 2028 | F202: Rolling Cart, Bowls (x2), Uno, Stickers (x5), Mini Clothespins (x10), Conditioner, Shampoo (NOT PICTURED) | G202: 21
A203: 45894 | B203: Pierinna Atoche | C203: patochevie@haverford.edu | D203: Kim/Tritton | E203: 2027 | F203: Minifridge (#83) | G203: 20
A204: 45894 | B204: Yassine Falah | C204: yfalah@haverford.edu | D204: Lloyd | E204: 2026 | F204: Standing Lamp | G204: 1
A205: 45894 | B205: Conner Mcwhan | C205: cmcwhan@haverford.edu | D205: HCA | E205: 2027 | F205: Desk Lamp | G205: 1
A206: 45894 | B206: Jonathan Lee | C206: jlee8@haverford.edu | D206: HCA | E206: 2027 | F206: Standing Lamp | G206: 1
A207: 45894 | B207: Vivian Ross | C207: vkross@haverford.edu | D207: HCA | E207: 2027 | F207: Tape | G207: 1
A208: 45894 | B208: Hijar Falah | C208: hfalah@haverford.edu | D208: Barclay | E208: 2028 | F208: Power Strip | G208: 1
...

Sheet Waitlist
A1: Date | B1: Requestor | C1: Email | D1: Housing Assignment | E1: Graduation Year | F1: Minifridge | G1: Lamp | H1: Fan | I1: Trashcan | J1: Other
B2: Eliana Kim | F2: FALSE | G2: FALSE | H2: FALSE | I2: TRUE | J2: Mirror
F3: FALSE | G3: FALSE | H3: FALSE | I3: FALSE
F4: FALSE | G4: FALSE | H4: FALSE | I4: FALSE
F5: FALSE | G5: FALSE | H5: FALSE | I5: FALSE
F6: FALSE | G6: FALSE | H6: FALSE | I6: FALSE
F7: FALSE | G7: FALSE | H7: FALSE | I7: FALSE
F8: FALSE | G8: FALSE | H8: FALSE | I8: FALSE
F9: FALSE | G9: FALSE | H9: FALSE | I9: FALSE
F10: FALSE | G10: FALSE | H10: FALSE | I10: FALSE
F11: FALSE | G11: FALSE | H11: FALSE | I11: FALSE
F12: FALSE | G12: FALSE | H12: FALSE | I12: FALSE
F13: FALSE | G13: FALSE | H13: FALSE | I13: FALSE
F14: FALSE | G14: FALSE | H14: FALSE | I14: FALSE
... F41: FALSE | G41: FALSE | H41: FALSE | I41: FALSE
F42: =COUNTIF(F2:F43,TRUE) -> #REF! | G42: =COUNTIF(G2:G43,TRUE) -> #REF! | H42: =COUNTIF(H2:H43,TRUE) -> #REF! | I42: =COUNTIF(I2:I43,TRUE) -> #REF!

Sheet Parameters
A1: Sheet | B1: Reference header | C1: Column
A2: Check-in | B2: Check-in date | C2: =IF(B2="","",LEFT(ADDRESS(1,MATCH(B2,INDIRECT("'"&A2&"'!$1:$1"),FALSE),4))) -> #N/A
A3: Check-in | B3: Quantity | C3: =IF(B3="","",LEFT(ADDRESS(1,MATCH(B3,INDIRECT("'"&A3&"'!$1:$1"),FALSE),4))) -> D
A4: Check-out | B4: Check-out date | C4: =IF(B4="","",LEFT(ADDRESS(1,MATCH(B4,INDIRECT("'"&A4&"'!$1:$1"),FALSE),4))) -> A
A5: Check-out | B5: Quantity | C5: =IF(B5="","",LEFT(ADDRESS(1,MATCH(B5,INDIRECT("'"&A5&"'!$1:$1"),FALSE),4))) -> D
A6: Current inventory list | B6: ='Current inventory list'!B1 -> Item name | C6: =IF(B6="","",LEFT(ADDRESS(1,MATCH(B6,INDIRECT("'"&A6&"'!$1:$1"),FALSE),4))) -> B
A7: Current inventory list | B7: ='Current inventory list'!D1 -> Check-in total | C7: =IF(B7="","",LEFT(ADDRESS(1,MATCH(B7,INDIRECT("'"&A7&"'!$1:$1"),FALSE),4))) -> D
C8: =IF(B8="","",LEFT(ADDRESS(1,MATCH(B8,INDIRECT("'"&A8&"'!$1:$1"),FALSE),4)))
C9: =IF(B9="","",LEFT(ADDRESS(1,MATCH(B9,INDIRECT("'"&A9&"'!$1:$1"),FALSE),4)))
C10: =IF(B10="","",LEFT(ADDRESS(1,MATCH(B10,INDIRECT("'"&A10&"'!$1:$1"),FALSE),4)))
C11: =IF(B11="","",LEFT(ADDRESS(1,MATCH(B11,INDIRECT("'"&A11&"'!$1:$1"),FALSE),4)))
C12: =IF(B12="","",LEFT(ADDRESS(1,MATCH(B12,INDIRECT("'"&A12&"'!$1:$1"),FALSE),4)))
C13: =IF(B13="","",LEFT(ADDRESS(1,MATCH(B13,INDIRECT("'"&A13&"'!$1:$1"),FALSE),4)))
C14: =IF(B14="","",LEFT(ADDRESS(1,MATCH(B14,INDIRECT("'"&A14&"'!$1:$1"),FALSE),4)))
C15: =IF(B15="","",LEFT(ADDRESS(1,MATCH(B15,INDIRECT("'"&A15&"'!$1:$1"),FALSE),4)))

Sheet Data preparation (Week analysis
A1: =IFERROR(__xludf.DUMMYFUNCTION("QUERY('Check-out'!A:Z,""SELECT ""&Parameters!C4&"",SUM(""&Parameters!C5&"") WHERE ""&Parameters!C5&"">0 GROUP BY ""&Parameters!C4&"" LABEL SUM(""&Parameters!C5&"") 'Total quantity'"")"),"Check-out date") -> Check-out date | B1: =IFERROR(__xludf.DUMMYFUNCTION("""COMPUTED_VALUE"""),"Total quantity") -> Total quantity | C1: {=IF(ROW(A1:A1001)=1,"Weekday",IF(A1:A1001="","",CHOOSE(WEEKDAY(A1:A1001,2),"Monday","Tuesday","Wednesday","Thursday","Friday","Saturday","Sunday")))} -> Weekday | D1: Weekday | E1: Average quantity
B2: =IFERROR(__xludf.DUMMYFUNCTION("""COMPUTED_VALUE"""),1.0) -> 1 | D2: Monday | E2: =AVERAGEIF(C:C,D2,B:B) -> #DIV/0!
D3: Tuesday | E3: =AVERAGEIF(C:C,D3,B:B) -> #DIV/0!
D4: Wednesday | E4: =AVERAGEIF(C:C,D4,B:B) -> #DIV/0!
D5: Thursday | E5: =AVERAGEIF(C:C,D5,B:B) -> #DIV/0!
D6: Friday | E6: =AVERAGEIF(C:C,D6,B:B) -> #DIV/0!
D7: Saturday | E7: =AVERAGEIF(C:C,D7,B:B) -> #DIV/0!
D8: Sunday | E8: =AVERAGEIF(C:C,D8,B:B) -> #DIV/0!

Sheet Data preparation (Last 15 days)
A1: Last 15 days | B1: In | C1: Out
A2: =A3-1 -> -14 | B2: {=SUMIF(INDIRECT("'Check-in'!"&Parameters!C$2&":"&Parameters!C$2&""),A2,INDIRECT("'Check-in'!"&Parameters!C$3&":"&Parameters!C$3&""))} -> 0 | C2: {=SUMIF(INDIRECT("'Check-out'!"&Parameters!C$4&":"&Parameters!C$4&""),A2,INDIRECT("'Check-out'!"&Parameters!C$5&":"&Parameters!C$5&""))} -> 0
A3: =A4-1 -> -13 | B3: {=SUMIF(INDIRECT("'Check-in'!"&Parameters!C$2&":"&Parameters!C$2&""),A3,INDIRECT("'Check-in'!"&Parameters!C$3&":"&Parameters!C$3&""))} -> 0 | C3: {=SUMIF(INDIRECT("'Check-out'!"&Parameters!C$4&":"&Parameters!C$4&""),A3,INDIRECT("'Check-out'!"&Parameters!C$5&":"&Parameters!C$5&""))} -> 0
A4: =A5-1 -> -12 | B4: {=SUMIF(INDIRECT("'Check-in'!"&Parameters!C$2&":"&Parameters!C$2&""),A4,INDIRECT("'Check-in'!"&Parameters!C$3&":"&Parameters!C$3&""))} -> 0 | C4: {=SUMIF(INDIRECT("'Check-out'!"&Parameters!C$4&":"&Parameters!C$4&""),A4,INDIRECT("'Check-out'!"&Parameters!C$5&":"&Parameters!C$5&""))} -> 0
A5: =A6-1 -> -11 | B5: {=SUMIF(INDIRECT("'Check-in'!"&Parameters!C$2&":"&Parameters!C$2&""),A5,INDIRECT("'Check-in'!"&Parameters!C$3&":"&Parameters!C$3&""))} -> 0 | C5: {=SUMIF(INDIRECT("'Check-out'!"&Parameters!C$4&":"&Parameters!C$4&""),A5,INDIRECT("'Check-out'!"&Parameters!C$5&":"&Parameters!C$5&""))} -> 0
A6: =A7-1 -> -10 | B6: {=SUMIF(INDIRECT("'Check-in'!"&Parameters!C$2&":"&Parameters!C$2&""),A6,INDIRECT("'Check-in'!"&Parameters!C$3&":"&Parameters!C$3&""))} -> 0 | C6: {=SUMIF(INDIRECT("'Check-out'!"&Parameters!C$4&":"&Parameters!C$4&""),A6,INDIRECT("'Check-out'!"&Parameters!C$5&":"&Parameters!C$5&""))} -> 0
A7: =A8-1 -> -9 | B7: {=SUMIF(INDIRECT("'Check-in'!"&Parameters!C$2&":"&Parameters!C$2&""),A7,INDIRECT("'Check-in'!"&Parameters!C$3&":"&Parameters!C$3&""))} -> 0 | C7: {=SUMIF(INDIRECT("'Check-out'!"&Parameters!C$4&":"&Parameters!C$4&""),A7,INDIRECT("'Check-out'!"&Parameters!C$5&":"&Parameters!C$5&""))} -> 0
A8: =A9-1 -> -8 | B8: {=SUMIF(INDIRECT("'Check-in'!"&Parameters!C$2&":"&Parameters!C$2&""),A8,INDIRECT("'Check-in'!"&Parameters!C$3&":"&Parameters!C$3&""))} -> 0 | C8: {=SUMIF(INDIRECT("'Check-out'!"&Parameters!C$4&":"&Parameters!C$4&""),A8,INDIRECT("'Check-out'!"&Parameters!C$5&":"&Parameters!C$5&""))} -> 0
A9: =A10-1 -> -7 | B9: {=SUMIF(INDIRECT("'Check-in'!"&Parameters!C$2&":"&Parameters!C$2&""),A9,INDIRECT("'Check-in'!"&Parameters!C$3&":"&Parameters!C$3&""))} -> 0 | C9: {=SUMIF(INDIRECT("'Check-out'!"&Parameters!C$4&":"&Parameters!C$4&""),A9,INDIRECT("'Check-out'!"&Parameters!C$5&":"&Parameters!C$5&""))} -> 0
A10: =A11-1 -> -6 | B10: {=SUMIF(INDIRECT("'Check-in'!"&Parameters!C$2&":"&Parameters!C$2&""),A10,INDIRECT("'Check-in'!"&Parameters!C$3&":"&Parameters!C$3&""))} -> 0 | C10: {=SUMIF(INDIRECT("'Check-out'!"&Parameters!C$4&":"&Parameters!C$4&""),A10,INDIRECT("'Check-out'!"&Parameters!C$5&":"&Parameters!C$5&""))} -> 0
A11: =A12-1 -> -5 | B11: {=SUMIF(INDIRECT("'Check-in'!"&Parameters!C$2&":"&Parameters!C$2&""),A11,INDIRECT("'Check-in'!"&Parameters!C$3&":"&Parameters!C$3&""))} -> 0 | C11: {=SUMIF(INDIRECT("'Check-out'!"&Parameters!C$4&":"&Parameters!C$4&""),A11,INDIRECT("'Check-out'!"&Parameters!C$5&":"&Parameters!C$5&""))} -> 0
A12: =A13-1 -> -4 | B12: {=SUMIF(INDIRECT("'Check-in'!"&Parameters!C$2&":"&Parameters!C$2&""),A12,INDIRECT("'Check-in'!"&Parameters!C$3&":"&Parameters!C$3&""))} -> 0 | C12: {=SUMIF(INDIRECT("'Check-out'!"&Parameters!C$4&":"&Parameters!C$4&""),A12,INDIRECT("'Check-out'!"&Parameters!C$5&":"&Parameters!C$5&""))} -> 0
A13: =A14-1 -> -3 | B13: {=SUMIF(INDIRECT("'Check-in'!"&Parameters!C$2&":"&Parameters!C$2&""),A13,INDIRECT("'Check-in'!"&Parameters!C$3&":"&Parameters!C$3&""))} -> 0 | C13: {=SUMIF(INDIRECT("'Check-out'!"&Parameters!C$4&":"&Parameters!C$4&""),A13,INDIRECT("'Check-out'!"&Parameters!C$5&":"&Parameters!C$5&""))} -> 0
... A15: =A16-1 -> -1 | B15: {=SUMIF(INDIRECT("'Check-in'!"&Parameters!C$2&":"&Parameters!C$2&""),A15,INDIRECT("'Check-in'!"&Parameters!C$3&":"&Parameters!C$3&""))} -> 0 | C15: {=SUMIF(INDIRECT("'Check-out'!"&Parameters!C$4&":"&Parameters!C$4&""),A15,INDIRECT("'Check-out'!"&Parameters!C$5&":"&Parameters!C$5&""))} -> 0
A16: =MAX('Check-out'!A2:A992) -> 0 | B16: {=SUMIF(INDIRECT("'Check-in'!"&Parameters!C$2&":"&Parameters!C$2&""),A16,INDIRECT("'Check-in'!"&Parameters!C$3&":"&Parameters!C$3&""))} -> 0 | C16: {=SUMIF(INDIRECT("'Check-out'!"&Parameters!C$4&":"&Parameters!C$4&""),A16,INDIRECT("'Check-out'!"&Parameters!C$5&":"&Parameters!C$5&""))} -> 0

Sheet Data preparation (Over sold ite
A1: Over sold items | E1: DIFF
A2: =IFERROR(__xludf.DUMMYFUNCTION("IFERROR(QUERY('Current inventory list'!A2:G15,""SELECT B WHERE F<0 LIMIT 9"",0),""None"")"),"Barware") -> Barware | E2: =IFERROR(__xludf.DUMMYFUNCTION("IFERROR(QUERY('Current inventory list'!A2:G15,""SELECT F WHERE F<0 LIMIT 9"",0),""None"")"),-1.0) -> -1
